2021-11-22 20:53:59,086 - INFO - 127.0.0.1 - - [22/Nov/2021 20:53:59] "[37mOPTIONS /api/addUser HTTP/1.1[0m" 200 -
2021-11-22 20:53:59,090 - INFO - start API add new user
2021-11-22 20:53:59,193 - INFO - 127.0.0.1 - - [22/Nov/2021 20:53:59] "[37mPOST /api/addUser HTTP/1.1[0m" 200 -
2021-11-22 20:54:28,883 - INFO - Start API
2021-11-22 20:54:28,885 - INFO - Flask started
2021-11-22 20:54:29,550 - INFO -  * Running on http://0.0.0.0:5000/ (Press CTRL+C to quit)
2021-11-22 20:54:40,514 - INFO - 127.0.0.1 - - [22/Nov/2021 20:54:40] "[37mOPTIONS /api/addUser HTTP/1.1[0m" 200 -
2021-11-22 20:54:40,517 - INFO - start API add new user
2021-11-22 20:54:41,053 - INFO - 127.0.0.1 - - [22/Nov/2021 20:54:41] "[37mPOST /api/addUser HTTP/1.1[0m" 200 -
2021-11-22 20:56:23,623 - INFO - start API get users list
2021-11-22 20:56:23,625 - ERROR - Exception on /api/users [GET]
Traceback (most recent call last):
  File "C:\Users\hiept\AppData\Local\Packages\PythonSoftwareFoundation.Python.3.8_qbz5n2kfra8p0\LocalCache\local-packages\Python38\site-packages\flask\app.py", line 2447, in wsgi_app
    response = self.full_dispatch_request()
  File "C:\Users\hiept\AppData\Local\Packages\PythonSoftwareFoundation.Python.3.8_qbz5n2kfra8p0\LocalCache\local-packages\Python38\site-packages\flask\app.py", line 1952, in full_dispatch_request
    rv = self.handle_user_exception(e)
  File "C:\Users\hiept\AppData\Local\Packages\PythonSoftwareFoundation.Python.3.8_qbz5n2kfra8p0\LocalCache\local-packages\Python38\site-packages\flask_cors\extension.py", line 165, in wrapped_function
    return cors_after_request(app.make_response(f(*args, **kwargs)))
  File "C:\Users\hiept\AppData\Local\Packages\PythonSoftwareFoundation.Python.3.8_qbz5n2kfra8p0\LocalCache\local-packages\Python38\site-packages\flask\app.py", line 1821, in handle_user_exception
    reraise(exc_type, exc_value, tb)
  File "C:\Users\hiept\AppData\Local\Packages\PythonSoftwareFoundation.Python.3.8_qbz5n2kfra8p0\LocalCache\local-packages\Python38\site-packages\flask\_compat.py", line 39, in reraise
    raise value
  File "C:\Users\hiept\AppData\Local\Packages\PythonSoftwareFoundation.Python.3.8_qbz5n2kfra8p0\LocalCache\local-packages\Python38\site-packages\flask\app.py", line 1950, in full_dispatch_request
    rv = self.dispatch_request()
  File "C:\Users\hiept\AppData\Local\Packages\PythonSoftwareFoundation.Python.3.8_qbz5n2kfra8p0\LocalCache\local-packages\Python38\site-packages\flask\app.py", line 1936, in dispatch_request
    return self.view_functions[rule.endpoint](**req.view_args)
  File ".\endpoint.py", line 162, in getUsers
    if(currentUser['role'] == 'superadmin'):
KeyError: 'role'
2021-11-22 20:56:23,771 - INFO - 127.0.0.1 - - [22/Nov/2021 20:56:23] "[35m[1mGET /api/users HTTP/1.1[0m" 500 -
2021-11-22 20:57:31,455 - INFO - Start API
2021-11-22 20:57:31,456 - INFO - Flask started
2021-11-22 20:57:31,903 - INFO -  * Running on http://0.0.0.0:5000/ (Press CTRL+C to quit)
2021-11-22 21:01:42,196 - INFO - start API get users list
2021-11-22 21:01:42,197 - ERROR - Exception on /api/users [GET]
Traceback (most recent call last):
  File "C:\Users\hiept\AppData\Local\Packages\PythonSoftwareFoundation.Python.3.8_qbz5n2kfra8p0\LocalCache\local-packages\Python38\site-packages\flask\app.py", line 2447, in wsgi_app
    response = self.full_dispatch_request()
  File "C:\Users\hiept\AppData\Local\Packages\PythonSoftwareFoundation.Python.3.8_qbz5n2kfra8p0\LocalCache\local-packages\Python38\site-packages\flask\app.py", line 1952, in full_dispatch_request
    rv = self.handle_user_exception(e)
  File "C:\Users\hiept\AppData\Local\Packages\PythonSoftwareFoundation.Python.3.8_qbz5n2kfra8p0\LocalCache\local-packages\Python38\site-packages\flask_cors\extension.py", line 165, in wrapped_function
    return cors_after_request(app.make_response(f(*args, **kwargs)))
  File "C:\Users\hiept\AppData\Local\Packages\PythonSoftwareFoundation.Python.3.8_qbz5n2kfra8p0\LocalCache\local-packages\Python38\site-packages\flask\app.py", line 1821, in handle_user_exception
    reraise(exc_type, exc_value, tb)
  File "C:\Users\hiept\AppData\Local\Packages\PythonSoftwareFoundation.Python.3.8_qbz5n2kfra8p0\LocalCache\local-packages\Python38\site-packages\flask\_compat.py", line 39, in reraise
    raise value
  File "C:\Users\hiept\AppData\Local\Packages\PythonSoftwareFoundation.Python.3.8_qbz5n2kfra8p0\LocalCache\local-packages\Python38\site-packages\flask\app.py", line 1950, in full_dispatch_request
    rv = self.dispatch_request()
  File "C:\Users\hiept\AppData\Local\Packages\PythonSoftwareFoundation.Python.3.8_qbz5n2kfra8p0\LocalCache\local-packages\Python38\site-packages\flask\app.py", line 1936, in dispatch_request
    return self.view_functions[rule.endpoint](**req.view_args)
  File ".\endpoint.py", line 162, in getUsers
    if(currentUser['role'] == 'superadmin'):
KeyError: 'role'
2021-11-22 21:01:42,202 - INFO - 127.0.0.1 - - [22/Nov/2021 21:01:42] "[35m[1mGET /api/users HTTP/1.1[0m" 500 -
2021-11-22 21:01:59,165 - INFO - 127.0.0.1 - - [22/Nov/2021 21:01:59] "[37mOPTIONS /api/login HTTP/1.1[0m" 200 -
2021-11-22 21:01:59,733 - INFO - 127.0.0.1 - - [22/Nov/2021 21:01:59] "[37mPOST /api/login HTTP/1.1[0m" 200 -
2021-11-22 21:01:59,805 - INFO - start API get info Dashboard
2021-11-22 21:01:59,986 - INFO - 127.0.0.1 - - [22/Nov/2021 21:01:59] "[37mGET /api/featureInfo/ HTTP/1.1[0m" 200 -
2021-11-22 21:02:00,182 - INFO - start API get dashboard list
2021-11-22 21:02:00,315 - INFO - 127.0.0.1 - - [22/Nov/2021 21:02:00] "[37mGET /api/dashboardList/ HTTP/1.1[0m" 200 -
2021-11-22 21:02:01,625 - INFO - start API get users list
2021-11-22 21:02:01,684 - ERROR - Exception on /api/users [GET]
Traceback (most recent call last):
  File "C:\Users\hiept\AppData\Local\Packages\PythonSoftwareFoundation.Python.3.8_qbz5n2kfra8p0\LocalCache\local-packages\Python38\site-packages\flask\app.py", line 2447, in wsgi_app
    response = self.full_dispatch_request()
  File "C:\Users\hiept\AppData\Local\Packages\PythonSoftwareFoundation.Python.3.8_qbz5n2kfra8p0\LocalCache\local-packages\Python38\site-packages\flask\app.py", line 1952, in full_dispatch_request
    rv = self.handle_user_exception(e)
  File "C:\Users\hiept\AppData\Local\Packages\PythonSoftwareFoundation.Python.3.8_qbz5n2kfra8p0\LocalCache\local-packages\Python38\site-packages\flask_cors\extension.py", line 165, in wrapped_function
    return cors_after_request(app.make_response(f(*args, **kwargs)))
  File "C:\Users\hiept\AppData\Local\Packages\PythonSoftwareFoundation.Python.3.8_qbz5n2kfra8p0\LocalCache\local-packages\Python38\site-packages\flask\app.py", line 1821, in handle_user_exception
    reraise(exc_type, exc_value, tb)
  File "C:\Users\hiept\AppData\Local\Packages\PythonSoftwareFoundation.Python.3.8_qbz5n2kfra8p0\LocalCache\local-packages\Python38\site-packages\flask\_compat.py", line 39, in reraise
    raise value
  File "C:\Users\hiept\AppData\Local\Packages\PythonSoftwareFoundation.Python.3.8_qbz5n2kfra8p0\LocalCache\local-packages\Python38\site-packages\flask\app.py", line 1950, in full_dispatch_request
    rv = self.dispatch_request()
  File "C:\Users\hiept\AppData\Local\Packages\PythonSoftwareFoundation.Python.3.8_qbz5n2kfra8p0\LocalCache\local-packages\Python38\site-packages\flask\app.py", line 1936, in dispatch_request
    return self.view_functions[rule.endpoint](**req.view_args)
  File ".\endpoint.py", line 172, in getUsers
    'dateRegistered': doc['dateRegistered'],
KeyError: 'dateRegistered'
2021-11-22 21:02:01,685 - INFO - 127.0.0.1 - - [22/Nov/2021 21:02:01] "[35m[1mGET /api/users HTTP/1.1[0m" 500 -
2021-11-22 21:02:10,453 - INFO - Start API
2021-11-22 21:02:10,454 - INFO - Flask started
2021-11-22 21:02:11,066 - INFO -  * Running on http://0.0.0.0:5000/ (Press CTRL+C to quit)
2021-11-22 21:02:12,203 - INFO - 127.0.0.1 - - [22/Nov/2021 21:02:12] "[32mGET /api/rectifierTransformerList HTTP/1.1[0m" 308 -
2021-11-22 21:02:12,380 - INFO - start API get Rectifier Transformers list
2021-11-22 21:02:12,381 - ERROR - Exception on /api/rectifierTransformerList/ [GET]
Traceback (most recent call last):
  File "C:\Users\hiept\AppData\Local\Packages\PythonSoftwareFoundation.Python.3.8_qbz5n2kfra8p0\LocalCache\local-packages\Python38\site-packages\flask\app.py", line 2447, in wsgi_app
    response = self.full_dispatch_request()
  File "C:\Users\hiept\AppData\Local\Packages\PythonSoftwareFoundation.Python.3.8_qbz5n2kfra8p0\LocalCache\local-packages\Python38\site-packages\flask\app.py", line 1952, in full_dispatch_request
    rv = self.handle_user_exception(e)
  File "C:\Users\hiept\AppData\Local\Packages\PythonSoftwareFoundation.Python.3.8_qbz5n2kfra8p0\LocalCache\local-packages\Python38\site-packages\flask_cors\extension.py", line 165, in wrapped_function
    return cors_after_request(app.make_response(f(*args, **kwargs)))
  File "C:\Users\hiept\AppData\Local\Packages\PythonSoftwareFoundation.Python.3.8_qbz5n2kfra8p0\LocalCache\local-packages\Python38\site-packages\flask\app.py", line 1821, in handle_user_exception
    reraise(exc_type, exc_value, tb)
  File "C:\Users\hiept\AppData\Local\Packages\PythonSoftwareFoundation.Python.3.8_qbz5n2kfra8p0\LocalCache\local-packages\Python38\site-packages\flask\_compat.py", line 39, in reraise
    raise value
  File "C:\Users\hiept\AppData\Local\Packages\PythonSoftwareFoundation.Python.3.8_qbz5n2kfra8p0\LocalCache\local-packages\Python38\site-packages\flask\app.py", line 1950, in full_dispatch_request
    rv = self.dispatch_request()
  File "C:\Users\hiept\AppData\Local\Packages\PythonSoftwareFoundation.Python.3.8_qbz5n2kfra8p0\LocalCache\local-packages\Python38\site-packages\flask\app.py", line 1936, in dispatch_request
    return self.view_functions[rule.endpoint](**req.view_args)
  File ".\endpoint.py", line 334, in getRectifier
    print(currentUser['role'])
KeyError: 'role'
2021-11-22 21:02:12,383 - INFO - 127.0.0.1 - - [22/Nov/2021 21:02:12] "[35m[1mGET /api/rectifierTransformerList/ HTTP/1.1[0m" 500 -
2021-11-22 21:02:13,778 - INFO - start API get users list
2021-11-22 21:02:13,778 - ERROR - Exception on /api/users [GET]
Traceback (most recent call last):
  File "C:\Users\hiept\AppData\Local\Packages\PythonSoftwareFoundation.Python.3.8_qbz5n2kfra8p0\LocalCache\local-packages\Python38\site-packages\flask\app.py", line 2447, in wsgi_app
    response = self.full_dispatch_request()
  File "C:\Users\hiept\AppData\Local\Packages\PythonSoftwareFoundation.Python.3.8_qbz5n2kfra8p0\LocalCache\local-packages\Python38\site-packages\flask\app.py", line 1952, in full_dispatch_request
    rv = self.handle_user_exception(e)
  File "C:\Users\hiept\AppData\Local\Packages\PythonSoftwareFoundation.Python.3.8_qbz5n2kfra8p0\LocalCache\local-packages\Python38\site-packages\flask_cors\extension.py", line 165, in wrapped_function
    return cors_after_request(app.make_response(f(*args, **kwargs)))
  File "C:\Users\hiept\AppData\Local\Packages\PythonSoftwareFoundation.Python.3.8_qbz5n2kfra8p0\LocalCache\local-packages\Python38\site-packages\flask\app.py", line 1821, in handle_user_exception
    reraise(exc_type, exc_value, tb)
  File "C:\Users\hiept\AppData\Local\Packages\PythonSoftwareFoundation.Python.3.8_qbz5n2kfra8p0\LocalCache\local-packages\Python38\site-packages\flask\_compat.py", line 39, in reraise
    raise value
  File "C:\Users\hiept\AppData\Local\Packages\PythonSoftwareFoundation.Python.3.8_qbz5n2kfra8p0\LocalCache\local-packages\Python38\site-packages\flask\app.py", line 1950, in full_dispatch_request
    rv = self.dispatch_request()
  File "C:\Users\hiept\AppData\Local\Packages\PythonSoftwareFoundation.Python.3.8_qbz5n2kfra8p0\LocalCache\local-packages\Python38\site-packages\flask\app.py", line 1936, in dispatch_request
    return self.view_functions[rule.endpoint](**req.view_args)
  File ".\endpoint.py", line 162, in getUsers
    if(currentUser['role'] == 'superadmin'):
KeyError: 'role'
2021-11-22 21:02:13,780 - INFO - 127.0.0.1 - - [22/Nov/2021 21:02:13] "[35m[1mGET /api/users HTTP/1.1[0m" 500 -
2021-11-22 21:02:18,719 - INFO - start API get users list
2021-11-22 21:02:18,719 - ERROR - Exception on /api/users [GET]
Traceback (most recent call last):
  File "C:\Users\hiept\AppData\Local\Packages\PythonSoftwareFoundation.Python.3.8_qbz5n2kfra8p0\LocalCache\local-packages\Python38\site-packages\flask\app.py", line 2447, in wsgi_app
    response = self.full_dispatch_request()
  File "C:\Users\hiept\AppData\Local\Packages\PythonSoftwareFoundation.Python.3.8_qbz5n2kfra8p0\LocalCache\local-packages\Python38\site-packages\flask\app.py", line 1952, in full_dispatch_request
    rv = self.handle_user_exception(e)
  File "C:\Users\hiept\AppData\Local\Packages\PythonSoftwareFoundation.Python.3.8_qbz5n2kfra8p0\LocalCache\local-packages\Python38\site-packages\flask_cors\extension.py", line 165, in wrapped_function
    return cors_after_request(app.make_response(f(*args, **kwargs)))
  File "C:\Users\hiept\AppData\Local\Packages\PythonSoftwareFoundation.Python.3.8_qbz5n2kfra8p0\LocalCache\local-packages\Python38\site-packages\flask\app.py", line 1821, in handle_user_exception
    reraise(exc_type, exc_value, tb)
  File "C:\Users\hiept\AppData\Local\Packages\PythonSoftwareFoundation.Python.3.8_qbz5n2kfra8p0\LocalCache\local-packages\Python38\site-packages\flask\_compat.py", line 39, in reraise
    raise value
  File "C:\Users\hiept\AppData\Local\Packages\PythonSoftwareFoundation.Python.3.8_qbz5n2kfra8p0\LocalCache\local-packages\Python38\site-packages\flask\app.py", line 1950, in full_dispatch_request
    rv = self.dispatch_request()
  File "C:\Users\hiept\AppData\Local\Packages\PythonSoftwareFoundation.Python.3.8_qbz5n2kfra8p0\LocalCache\local-packages\Python38\site-packages\flask\app.py", line 1936, in dispatch_request
    return self.view_functions[rule.endpoint](**req.view_args)
  File ".\endpoint.py", line 162, in getUsers
    if(currentUser['role'] == 'superadmin'):
KeyError: 'role'
2021-11-22 21:02:18,721 - INFO - 127.0.0.1 - - [22/Nov/2021 21:02:18] "[35m[1mGET /api/users HTTP/1.1[0m" 500 -
2021-11-22 21:02:27,661 - INFO - 127.0.0.1 - - [22/Nov/2021 21:02:27] "[37mOPTIONS /api/login HTTP/1.1[0m" 200 -
2021-11-22 21:02:28,092 - INFO - 127.0.0.1 - - [22/Nov/2021 21:02:28] "[37mPOST /api/login HTTP/1.1[0m" 200 -
2021-11-22 21:02:28,167 - INFO - start API get info Dashboard
2021-11-22 21:02:28,310 - INFO - 127.0.0.1 - - [22/Nov/2021 21:02:28] "[37mGET /api/featureInfo/ HTTP/1.1[0m" 200 -
2021-11-22 21:02:28,551 - INFO - start API get dashboard list
2021-11-22 21:02:28,687 - INFO - 127.0.0.1 - - [22/Nov/2021 21:02:28] "[37mGET /api/dashboardList/ HTTP/1.1[0m" 200 -
2021-11-22 21:02:29,810 - INFO - start API get users list
2021-11-22 21:02:29,858 - ERROR - Exception on /api/users [GET]
Traceback (most recent call last):
  File "C:\Users\hiept\AppData\Local\Packages\PythonSoftwareFoundation.Python.3.8_qbz5n2kfra8p0\LocalCache\local-packages\Python38\site-packages\flask\app.py", line 2447, in wsgi_app
    response = self.full_dispatch_request()
  File "C:\Users\hiept\AppData\Local\Packages\PythonSoftwareFoundation.Python.3.8_qbz5n2kfra8p0\LocalCache\local-packages\Python38\site-packages\flask\app.py", line 1952, in full_dispatch_request
    rv = self.handle_user_exception(e)
  File "C:\Users\hiept\AppData\Local\Packages\PythonSoftwareFoundation.Python.3.8_qbz5n2kfra8p0\LocalCache\local-packages\Python38\site-packages\flask_cors\extension.py", line 165, in wrapped_function
    return cors_after_request(app.make_response(f(*args, **kwargs)))
  File "C:\Users\hiept\AppData\Local\Packages\PythonSoftwareFoundation.Python.3.8_qbz5n2kfra8p0\LocalCache\local-packages\Python38\site-packages\flask\app.py", line 1821, in handle_user_exception
    reraise(exc_type, exc_value, tb)
  File "C:\Users\hiept\AppData\Local\Packages\PythonSoftwareFoundation.Python.3.8_qbz5n2kfra8p0\LocalCache\local-packages\Python38\site-packages\flask\_compat.py", line 39, in reraise
    raise value
  File "C:\Users\hiept\AppData\Local\Packages\PythonSoftwareFoundation.Python.3.8_qbz5n2kfra8p0\LocalCache\local-packages\Python38\site-packages\flask\app.py", line 1950, in full_dispatch_request
    rv = self.dispatch_request()
  File "C:\Users\hiept\AppData\Local\Packages\PythonSoftwareFoundation.Python.3.8_qbz5n2kfra8p0\LocalCache\local-packages\Python38\site-packages\flask\app.py", line 1936, in dispatch_request
    return self.view_functions[rule.endpoint](**req.view_args)
  File ".\endpoint.py", line 172, in getUsers
    'dateRegistered': doc['dateRegistered'],
KeyError: 'dateRegistered'
2021-11-22 21:02:29,859 - INFO - 127.0.0.1 - - [22/Nov/2021 21:02:29] "[35m[1mGET /api/users HTTP/1.1[0m" 500 -
2021-11-22 21:04:56,888 - INFO - 127.0.0.1 - - [22/Nov/2021 21:04:56] "[37mOPTIONS /api/login HTTP/1.1[0m" 200 -
2021-11-22 21:04:56,950 - INFO - 127.0.0.1 - - [22/Nov/2021 21:04:56] "[37mPOST /api/login HTTP/1.1[0m" 200 -
2021-11-22 21:04:57,069 - INFO - start API get info Dashboard
2021-11-22 21:04:57,204 - INFO - 127.0.0.1 - - [22/Nov/2021 21:04:57] "[37mGET /api/featureInfo/ HTTP/1.1[0m" 200 -
2021-11-22 21:04:57,419 - INFO - start API get dashboard list
2021-11-22 21:04:57,627 - INFO - 127.0.0.1 - - [22/Nov/2021 21:04:57] "[37mGET /api/dashboardList/ HTTP/1.1[0m" 200 -
2021-11-22 21:04:58,479 - INFO - start API get users list
2021-11-22 21:04:58,531 - INFO - 127.0.0.1 - - [22/Nov/2021 21:04:58] "[37mGET /api/users HTTP/1.1[0m" 200 -
2021-11-22 21:05:05,736 - INFO - start API get users list
2021-11-22 21:05:05,788 - INFO - 127.0.0.1 - - [22/Nov/2021 21:05:05] "[37mGET /api/users HTTP/1.1[0m" 200 -
2021-11-22 21:05:25,569 - INFO - start API get users list
2021-11-22 21:05:25,768 - INFO - 127.0.0.1 - - [22/Nov/2021 21:05:25] "[37mGET /api/users HTTP/1.1[0m" 200 -
2021-11-22 21:05:52,553 - INFO - 127.0.0.1 - - [22/Nov/2021 21:05:52] "[37mOPTIONS /api/addUser HTTP/1.1[0m" 200 -
2021-11-22 21:05:52,556 - INFO - start API add new user
2021-11-22 21:05:53,703 - INFO - 127.0.0.1 - - [22/Nov/2021 21:05:53] "[37mPOST /api/addUser HTTP/1.1[0m" 200 -
2021-11-22 21:05:55,486 - INFO - start API get users list
2021-11-22 21:05:55,569 - INFO - 127.0.0.1 - - [22/Nov/2021 21:05:55] "[37mGET /api/users HTTP/1.1[0m" 200 -
2021-11-22 21:06:37,448 - INFO - start API get users list
2021-11-22 21:06:37,492 - INFO - 127.0.0.1 - - [22/Nov/2021 21:06:37] "[37mGET /api/users HTTP/1.1[0m" 200 -
2021-11-22 21:07:05,666 - INFO - start API get users list
2021-11-22 21:07:05,712 - INFO - 127.0.0.1 - - [22/Nov/2021 21:07:05] "[37mGET /api/users HTTP/1.1[0m" 200 -
2021-11-22 21:07:15,534 - INFO - start API get users list
2021-11-22 21:07:15,582 - INFO - 127.0.0.1 - - [22/Nov/2021 21:07:15] "[37mGET /api/users HTTP/1.1[0m" 200 -
2021-11-22 21:07:24,829 - INFO - start API get users list
2021-11-22 21:07:24,884 - INFO - 127.0.0.1 - - [22/Nov/2021 21:07:24] "[37mGET /api/users HTTP/1.1[0m" 200 -
2021-11-22 21:07:30,486 - INFO - start API get users list
2021-11-22 21:07:30,539 - INFO - 127.0.0.1 - - [22/Nov/2021 21:07:30] "[37mGET /api/users HTTP/1.1[0m" 200 -
2021-11-22 21:07:32,912 - INFO - start API get Rectifier Transformers list
2021-11-22 21:07:33,004 - INFO - 127.0.0.1 - - [22/Nov/2021 21:07:33] "[37mGET /api/rectifierTransformerList/ HTTP/1.1[0m" 200 -
2021-11-22 21:07:33,785 - INFO - start API get users list
2021-11-22 21:07:33,829 - INFO - 127.0.0.1 - - [22/Nov/2021 21:07:33] "[37mGET /api/users HTTP/1.1[0m" 200 -
2021-11-22 21:07:41,042 - INFO - start API get Rectifier Transformers list
2021-11-22 21:07:41,135 - INFO - 127.0.0.1 - - [22/Nov/2021 21:07:41] "[37mGET /api/rectifierTransformerList/ HTTP/1.1[0m" 200 -
2021-11-22 21:07:41,341 - INFO - start API get users list
2021-11-22 21:07:41,386 - INFO - 127.0.0.1 - - [22/Nov/2021 21:07:41] "[37mGET /api/users HTTP/1.1[0m" 200 -
2021-11-22 21:07:45,712 - INFO - start API get users list
2021-11-22 21:07:45,758 - INFO - 127.0.0.1 - - [22/Nov/2021 21:07:45] "[37mGET /api/users HTTP/1.1[0m" 200 -
2021-11-22 21:08:17,068 - INFO - 127.0.0.1 - - [22/Nov/2021 21:08:17] "[37mGET /api/users/619ba2102cfe53e6e30791cf HTTP/1.1[0m" 200 -
2021-11-22 21:09:00,376 - INFO - 127.0.0.1 - - [22/Nov/2021 21:09:00] "[37mGET /api/users/619ba2102cfe53e6e30791cf HTTP/1.1[0m" 200 -
2021-11-22 21:09:11,376 - INFO - 127.0.0.1 - - [22/Nov/2021 21:09:11] "[37mGET /api/users/619ba2102cfe53e6e30791cf HTTP/1.1[0m" 200 -
2021-11-22 21:09:22,023 - INFO - 127.0.0.1 - - [22/Nov/2021 21:09:22] "[37mGET /api/users/619ba2102cfe53e6e30791cf HTTP/1.1[0m" 200 -
2021-11-22 21:09:24,518 - INFO - 127.0.0.1 - - [22/Nov/2021 21:09:24] "[37mGET /api/users/619ba2102cfe53e6e30791cf HTTP/1.1[0m" 200 -
2021-11-22 21:09:35,756 - INFO - 127.0.0.1 - - [22/Nov/2021 21:09:35] "[37mGET /api/users/619ba2102cfe53e6e30791cf HTTP/1.1[0m" 200 -
2021-11-22 21:09:40,508 - INFO - 127.0.0.1 - - [22/Nov/2021 21:09:40] "[37mGET /api/users/619ba2102cfe53e6e30791cf HTTP/1.1[0m" 200 -
2021-11-22 21:10:16,542 - INFO - 127.0.0.1 - - [22/Nov/2021 21:10:16] "[37mGET /api/users/619ba2102cfe53e6e30791cf HTTP/1.1[0m" 200 -
2021-11-22 21:10:29,373 - INFO - 127.0.0.1 - - [22/Nov/2021 21:10:29] "[37mGET /api/users/619ba2102cfe53e6e30791cf HTTP/1.1[0m" 200 -
2021-11-22 21:18:44,878 - INFO - 127.0.0.1 - - [22/Nov/2021 21:18:44] "[37mGET /api/users/619ba2102cfe53e6e30791cf HTTP/1.1[0m" 200 -
2021-11-22 21:18:47,628 - INFO - 127.0.0.1 - - [22/Nov/2021 21:18:47] "[37mGET /api/users/619ba2102cfe53e6e30791cf HTTP/1.1[0m" 200 -
2021-11-22 21:20:25,217 - INFO - start API get users list
2021-11-22 21:20:25,261 - INFO - 127.0.0.1 - - [22/Nov/2021 21:20:25] "[37mGET /api/users HTTP/1.1[0m" 200 -
2021-11-22 21:21:57,588 - INFO - start API get Rectifier Transformers list
2021-11-22 21:21:57,767 - INFO - 127.0.0.1 - - [22/Nov/2021 21:21:57] "[37mGET /api/rectifierTransformerList/ HTTP/1.1[0m" 200 -
2021-11-22 21:47:27,529 - INFO - start API get Rectifier Transformers list
2021-11-22 21:47:27,624 - INFO - 127.0.0.1 - - [22/Nov/2021 21:47:27] "[37mGET /api/rectifierTransformerList/ HTTP/1.1[0m" 200 -
